<rss version="2.0" xmlns:atom="http://www.w3.org/2005/Atom">
  <channel>
    <title>MySQL on The Official Site of siBunglon</title>
    <link>https://sibunglon.com/tags/mysql/</link>
    <description>Recent content in MySQL on The Official Site of siBunglon</description>
    <generator>Hugo -- gohugo.io</generator>
    <language>en-us</language>
    <lastBuildDate>Sat, 05 Sep 2020 02:54:59 +0800</lastBuildDate>
    
      <atom:link href="https://sibunglon.com/tags/mysql/index.xml" rel="self" type="application/rss+xml" />
    
    
      <item>
        <title>Create a Read Only MySQL User</title>
        <link>https://sibunglon.com/2020/09/05/create-a-read-only-mysql-user/</link>
        <pubDate>Sat, 05 Sep 2020 02:54:59 +0800</pubDate>
        <guid>https://sibunglon.com/2020/09/05/create-a-read-only-mysql-user/</guid>
        <description>There are times when you need account read only access to a database.
To create a read only database user MySQL, do the following steps:
  Login as a MySQL administrator.
  Create a new MySQL user account.
  &amp;gt;&amp;gt;&amp;gt; CREATE USER &amp;#39;dapenda&amp;#39;@&amp;#39;%&amp;#39; IDENTIFIED BY &amp;#39;mypassword&amp;#39;; Grant the SELECT only privilege to user.  &amp;gt;&amp;gt;&amp;gt; GRANT SELECT ON site.* TO &amp;#39;dapenda&amp;#39;@&amp;#39;%&amp;#39;; Reload grant privilege for re-read access table MySQL.</description>
      </item>
    
      <item>
        <title>Database returned an invalid value in QuerySet.datetimes()</title>
        <link>https://sibunglon.com/2020/07/26/database-returned-an-invalid-value-in-queryset.datetimes/</link>
        <pubDate>Sun, 26 Jul 2020 21:05:49 +0800</pubDate>
        <guid>https://sibunglon.com/2020/07/26/database-returned-an-invalid-value-in-queryset.datetimes/</guid>
        <description>After create new action on the Django admin pages, it redirects to my site with the message a server error. When check the file /edx/var/log/supervisor/lms-stderr.log i find this:
Traceback (most recent call last): File &amp;quot;/edx/app/edxapp/venvs/edxapp/local/lib/python2.7/site-packages/django/core/handlers/exception.py&amp;quot;, line 41, in inner response = get_response(request) File &amp;quot;/edx/app/edxapp/venvs/edxapp/local/lib/python2.7/site-packages/django/core/handlers/base.py&amp;quot;, line 249, in _legacy_get_response response = self._get_response(request) File &amp;quot;/edx/app/edxapp/venvs/edxapp/local/lib/python2.7/site-packages/django/core/handlers/base.py&amp;quot;, line 217, in _get_response response = self.process_exception_by_middleware(e, request) File &amp;quot;/edx/app/edxapp/venvs/edxapp/local/lib/python2.7/site-packages/django/core/handlers/base.py&amp;quot;, line 215, in _get_response response = response.render() File &amp;quot;/edx/app/edxapp/venvs/edxapp/local/lib/python2.</description>
      </item>
    
      <item>
        <title>Error Install MySQL Server on Ubuntu 18</title>
        <link>https://sibunglon.com/2020/02/07/error-install-mysql-server-on-ubuntu-18/</link>
        <pubDate>Fri, 07 Feb 2020 23:55:13 +0700</pubDate>
        <guid>https://sibunglon.com/2020/02/07/error-install-mysql-server-on-ubuntu-18/</guid>
        <description>A few days ago mysql server was installed again, mysql was successfully installed and the service was successfully running but if you want to install another package, this problem must be solved by installing mysql server because mysql server installation is not 100% complete yet.
Btw, fortunately the terminal history on the laptop has not been cleared so I can save the error message again on Ubuntu pastebin so that others can see the error clearly üòÅ.</description>
      </item>
    
  </channel>
</rss>
